<?xml version="1.0" encoding="utf-8"?>
<!-- This URDF was automatically created by SolidWorks to URDF Exporter! Originally created by Stephen Brawner (brawner@gmail.com) 
     Commit Version: 1.6.0-4-g7f85cfe  Build Version: 1.6.7995.38578
     For more information, please see http://wiki.ros.org/sw_urdf_exporter -->
<robot xmlns:xacro="http://www.ros.org/wiki/xacro" name="modulo_diferencial">
  <xacro:macro name="build_module" params="prefix">
    <link
      name="${prefix}_link_soporte_motrices">
      <inertial>
        <origin
          xyz="0 -1.1102E-16 0.063082"
          rpy="0 0 0" />
        <mass
          value="1.7465" />
        <inertia
          ixx="0.0043382"
          ixy="-1.1032E-18"
          ixz="-3.4253E-20"
          iyy="0.00072632"
          iyz="-2.6685E-18"
          izz="0.0047839" />
      </inertial>
      <visual>
        <origin
          xyz="0 0 0"
          rpy="0 0 0" />
        <geometry>
          <mesh
            filename="file://$(find carrolac_description)/meshes/link_soporte_motrices.STL" />
        </geometry>
        <material
          name="">
          <color
            rgba="0.3 1.0 0.3 1" />
        </material>
      </visual>
      <collision>
        <origin
          xyz="0 0 0"
          rpy="0 0 0" />
        <geometry>
          <mesh
            filename="file://$(find carrolac_description)/meshes/link_soporte_motrices.STL" />
        </geometry>
      </collision>
    </link>
    <link
      name="${prefix}_link_rueda_izq">
      <inertial>
        <origin
          xyz="-2.5108E-13 4.7135E-13 -0.058116"
          rpy="0 0 0" />
        <mass
          value="0.97672" />
        <inertia
          ixx="0.0016522"
          ixy="-2.233E-17"
          ixz="-4.7071E-15"
          iyy="0.0016522"
          iyz="8.836E-15"
          izz="0.0028863" />
      </inertial>
      <visual>
        <origin
          xyz="0 0 0"
          rpy="0 0 0" />
        <geometry>
          <mesh
            filename="file://$(find carrolac_description)/meshes/link_rueda_izq.STL" />
        </geometry>
        <material
          name="">
          <color
            rgba="0.2 0.2 0.2 1" />
        </material>
      </visual>
      <collision>
        <origin
          xyz="0 0 0"
          rpy="0 0 0" />
        <geometry>
          <mesh
            filename="file://$(find carrolac_description)/meshes/link_rueda_izq.STL" />
        </geometry>
      </collision>
    </link>
    <joint
      name="${prefix}_joint_rueda_izq"
      type="continuous">
      <origin
        xyz="0 -0.1875 0.1065"
        rpy="-1.5708 0 0" />
      <parent
        link="${prefix}_link_soporte_motrices" />
      <child
        link="${prefix}_link_rueda_izq" />
      <axis
        xyz="0 0 1" />
    </joint>
    <link
      name="${prefix}_link_rueda_der">
      <inertial>
        <origin
          xyz="2.5091E-13 4.7068E-13 0.058116"
          rpy="0 0 0" />
        <mass
          value="0.97672" />
        <inertia
          ixx="0.0016522"
          ixy="2.2278E-17"
          ixz="-4.7079E-15"
          iyy="0.0016522"
          iyz="-8.836E-15"
          izz="0.0028863" />
      </inertial>
      <visual>
        <origin
          xyz="0 0 0"
          rpy="0 0 0" />
        <geometry>
          <mesh
            filename="file://$(find carrolac_description)/meshes/link_rueda_der.STL" />
        </geometry>
        <material
          name="">
          <color
            rgba="0.2 0.2 0.2 1" />
        </material>
      </visual>
      <collision>
        <origin
          xyz="0 0 0"
          rpy="0 0 0" />
        <geometry>
          <mesh
            filename="file://$(find carrolac_description)/meshes/link_rueda_der.STL" />
        </geometry>
      </collision>
    </link>
    <joint
      name="${prefix}_joint_rueda_der"
      type="continuous">
      <origin
        xyz="0 0.1875 0.1065"
        rpy="-1.5708 0 0" />
      <parent
        link="${prefix}_link_soporte_motrices" />
      <child
        link="${prefix}_link_rueda_der" />
      <axis
        xyz="0 0 1" />
    </joint>
    <ros2_control name="${prefix}_control" type="system">
      <hardware>
        <plugin>ign_ros2_control/IgnitionSystem</plugin>
      </hardware>
      <joint name="${prefix}_joint_rueda_izq">
        <command_interface name="velocity">
          <param name="min">-10</param>
          <param name="max">10</param>
        </command_interface>
        <state_interface name="position"/>
        <state_interface name="velocity"/>
        <state_interface name="effort"/>
      </joint>
      <joint name="${prefix}_joint_rueda_der">
        <command_interface name="velocity">
          <param name="min">-10</param>
          <param name="max">10</param>
        </command_interface>
        <state_interface name="position"/>
        <state_interface name="velocity"/>
        <state_interface name="effort"/>
      </joint>
      <sensor name="modsensorsD_imu_sensor">
        <state_interface name="orientation.x"/>
        <state_interface name="orientation.y"/>
        <state_interface name="orientation.z"/>
        <state_interface name="orientation.w"/>
        <state_interface name="angular_velocity.x"/>
        <state_interface name="angular_velocity.y"/>
        <state_interface name="angular_velocity.z"/>
        <state_interface name="linear_acceleration.x"/>
        <state_interface name="linear_acceleration.y"/>
        <state_interface name="linear_acceleration.z"/>
      </sensor>
    </ros2_control>
  </xacro:macro>
</robot>
