<?xml version="1.0" ?>
<!-- =================================================================================== -->
<!-- |    This document was autogenerated by xacro from carrolac_td_sensors.urdf.xacro | -->
<!-- |    EDITING THIS FILE BY HAND IS NOT RECOMMENDED                                 | -->
<!-- =================================================================================== -->
<robot name="carrolac_v2">
  <material name="blue">
    <color rgba="0 0 0.8 1"/>
  </material>
  <material name="white">
    <color rgba="1 1 1 1"/>
  </material>
  <material name="red">
    <color rgba="0.8 0 0 1"/>
  </material>
  <material name="yellow">
    <color rgba="1 1 0.3 1"/>
  </material>
  <link name="link_base">
    <inertial>
      <origin rpy="0 0 0" xyz="0.000 0.000 0.018"/>
      <mass value="13.348"/>
      <inertia ixx="0.430" ixy="0.000" ixz="0.000" iyy="0.462" iyz="0.000" izz="0.868"/>
    </inertial>
    <visual>
      <geometry>
        <mesh filename="file:///home/duser/install/carrolac_description/share/carrolac_description/meshes/CHASIS_03.STL" scale="1 1 1"/>
      </geometry>
      <material name="yellow"/>
    </visual>
    <collision>
      <geometry>
        <mesh filename="file:///home/duser/install/carrolac_description/share/carrolac_description/meshes/CHASIS_03.STL" scale="1 1 1"/>
      </geometry>
    </collision>
  </link>
  <!--xacro:build_module prefix="md00"/-->
  <link name="moddifT_link_soporte_motrices">
    <inertial>
      <origin rpy="0 0 0" xyz="0 -1.1102E-16 0.063082"/>
      <mass value="1.7465"/>
      <inertia ixx="0.0043382" ixy="-1.1032E-18" ixz="-3.4253E-20" iyy="0.00072632" iyz="-2.6685E-18" izz="0.0047839"/>
    </inertial>
    <visual>
      <origin rpy="0 0 0" xyz="0 0 0"/>
      <geometry>
        <mesh filename="file:///home/duser/install/carrolac_description/share/carrolac_description/meshes/link_soporte_motrices.STL"/>
      </geometry>
      <material name="">
        <color rgba="0.3 1.0 0.3 1"/>
      </material>
    </visual>
    <collision>
      <origin rpy="0 0 0" xyz="0 0 0"/>
      <geometry>
        <mesh filename="file:///home/duser/install/carrolac_description/share/carrolac_description/meshes/link_soporte_motrices.STL"/>
      </geometry>
    </collision>
  </link>
  <link name="moddifT_link_rueda_izq">
    <inertial>
      <origin rpy="0 0 0" xyz="-2.5108E-13 4.7135E-13 -0.058116"/>
      <mass value="0.97672"/>
      <inertia ixx="0.0016522" ixy="-2.233E-17" ixz="-4.7071E-15" iyy="0.0016522" iyz="8.836E-15" izz="0.0028863"/>
    </inertial>
    <visual>
      <origin rpy="0 0 0" xyz="0 0 0"/>
      <geometry>
        <mesh filename="file:///home/duser/install/carrolac_description/share/carrolac_description/meshes/link_rueda_izq.STL"/>
      </geometry>
      <material name="">
        <color rgba="0.2 0.2 0.2 1"/>
      </material>
    </visual>
    <collision>
      <origin rpy="0 0 0" xyz="0 0 0"/>
      <geometry>
        <mesh filename="file:///home/duser/install/carrolac_description/share/carrolac_description/meshes/link_rueda_izq.STL"/>
      </geometry>
    </collision>
  </link>
  <joint name="moddifT_joint_rueda_izq" type="continuous">
    <origin rpy="-1.5708 0 0" xyz="0 -0.1875 0.1065"/>
    <parent link="moddifT_link_soporte_motrices"/>
    <child link="moddifT_link_rueda_izq"/>
    <axis xyz="0 0 1"/>
  </joint>
  <link name="moddifT_link_rueda_der">
    <inertial>
      <origin rpy="0 0 0" xyz="2.5091E-13 4.7068E-13 0.058116"/>
      <mass value="0.97672"/>
      <inertia ixx="0.0016522" ixy="2.2278E-17" ixz="-4.7079E-15" iyy="0.0016522" iyz="-8.836E-15" izz="0.0028863"/>
    </inertial>
    <visual>
      <origin rpy="0 0 0" xyz="0 0 0"/>
      <geometry>
        <mesh filename="file:///home/duser/install/carrolac_description/share/carrolac_description/meshes/link_rueda_der.STL"/>
      </geometry>
      <material name="">
        <color rgba="0.2 0.2 0.2 1"/>
      </material>
    </visual>
    <collision>
      <origin rpy="0 0 0" xyz="0 0 0"/>
      <geometry>
        <mesh filename="file:///home/duser/install/carrolac_description/share/carrolac_description/meshes/link_rueda_der.STL"/>
      </geometry>
    </collision>
  </link>
  <joint name="moddifT_joint_rueda_der" type="continuous">
    <origin rpy="-1.5708 0 0" xyz="0 0.1875 0.1065"/>
    <parent link="moddifT_link_soporte_motrices"/>
    <child link="moddifT_link_rueda_der"/>
    <axis xyz="0 0 1"/>
  </joint>
  <ros2_control name="moddifT_control" type="system">
    <hardware>
      <plugin>ign_ros2_control/IgnitionSystem</plugin>
    </hardware>
    <joint name="moddifT_joint_rueda_izq">
      <command_interface name="velocity">
        <param name="min">-10</param>
        <param name="max">10</param>
      </command_interface>
      <state_interface name="position"/>
      <state_interface name="velocity"/>
      <state_interface name="effort"/>
    </joint>
    <joint name="moddifT_joint_rueda_der">
      <command_interface name="velocity">
        <param name="min">-10</param>
        <param name="max">10</param>
      </command_interface>
      <state_interface name="position"/>
      <state_interface name="velocity"/>
      <state_interface name="effort"/>
    </joint>
    <sensor name="modsensorsD_imu_sensor">
      <state_interface name="orientation.x"/>
      <state_interface name="orientation.y"/>
      <state_interface name="orientation.z"/>
      <state_interface name="orientation.w"/>
      <state_interface name="angular_velocity.x"/>
      <state_interface name="angular_velocity.y"/>
      <state_interface name="angular_velocity.z"/>
      <state_interface name="linear_acceleration.x"/>
      <state_interface name="linear_acceleration.y"/>
      <state_interface name="linear_acceleration.z"/>
    </sensor>
  </ros2_control>
  <joint name="moddifT_joint_modulo_diferencial" type="fixed">
    <origin rpy="3.1415 0 0" xyz="-0.240 0.000 -0.022"/>
    <parent link="link_base"/>
    <child link="moddifT_link_soporte_motrices"/>
  </joint>
  <link name="casterD_link_brida">
    <inertial>
      <origin rpy="0 0 0" xyz="-5.2042E-18 0 0.0017221"/>
      <mass value="0.2362"/>
      <inertia ixx="0.0002074" ixy="-8.6231E-20" ixz="-4.1413E-22" iyy="0.00030568" iyz="-8.399E-22" izz="0.00051259"/>
    </inertial>
    <visual>
      <origin rpy="0 0 0" xyz="0 0 0"/>
      <geometry>
        <mesh filename="file:///home/duser/install/carrolac_description/share/carrolac_description/meshes/link_brida.STL"/>
      </geometry>
      <material name="">
        <color rgba="0.8 0.0 0.0 1"/>
      </material>
    </visual>
    <collision>
      <origin rpy="0 0 0" xyz="0 0 0"/>
      <geometry>
        <mesh filename="file:///home/duser/install/carrolac_description/share/carrolac_description/meshes/link_brida.STL"/>
      </geometry>
    </collision>
  </link>
  <link name="casterD_link_horquilla">
    <inertial>
      <origin rpy="0 0 0" xyz="1.8908E-07 0.02249 0.050761"/>
      <mass value="0.072224"/>
      <inertia ixx="0.00012363" ixy="8.8179E-10" ixz="4.1929E-10" iyy="0.0001408" iyz="-3.5406E-05" izz="0.000144"/>
    </inertial>
    <visual>
      <origin rpy="0 0 0" xyz="0 0 0"/>
      <geometry>
        <mesh filename="file:///home/duser/install/carrolac_description/share/carrolac_description/meshes/link_horquilla.STL"/>
      </geometry>
      <material name="">
        <color rgba="1.0 1.0 1.0 1"/>
      </material>
    </visual>
    <collision>
      <origin rpy="0 0 0" xyz="0 0 0"/>
      <geometry>
        <mesh filename="file:///home/duser/install/carrolac_description/share/carrolac_description/meshes/link_horquilla.STL"/>
      </geometry>
    </collision>
  </link>
  <joint name="casterD_joint_horquilla" type="continuous">
    <origin rpy="0 0 0" xyz="0 0 0.002"/>
    <parent link="casterD_link_brida"/>
    <child link="casterD_link_horquilla"/>
    <axis xyz="0 0 1"/>
  </joint>
  <link name="casterD_link_rueda">
    <inertial>
      <origin rpy="0 0 0" xyz="0.016549 0.029538 -0.010744"/>
      <mass value="0.97447"/>
      <inertia ixx="0.0036205" ixy="-0.0011336" ixz="-1.1597E-09" iyy="0.0024449" iyz="-7.6933E-10" izz="0.0051466"/>
    </inertial>
    <visual>
      <origin rpy="0 0 0" xyz="0 0 0"/>
      <geometry>
        <mesh filename="file:///home/duser/install/carrolac_description/share/carrolac_description/meshes/link_rueda.STL"/>
      </geometry>
      <material name="">
        <color rgba="0.2 0.2 0.2 1"/>
      </material>
    </visual>
    <collision>
      <origin rpy="0 0 0" xyz="0 0 0"/>
      <geometry>
        <mesh filename="file:///home/duser/install/carrolac_description/share/carrolac_description/meshes/link_rueda.STL"/>
      </geometry>
    </collision>
  </link>
  <gazebo reference="casterD_link_rueda">
    <collision>
      <surface>
        <contact>
          <elastic_modulus>1</elastic_modulus>
          <ode>
            <kp>1</kp>
          </ode>
        </contact>
      </surface>
    </collision>
  </gazebo>
  <joint name="casterD_joint_rueda" type="continuous">
    <origin rpy="-1.5708 0 -1.5708" xyz="0.010744 0.057553 0.105"/>
    <parent link="casterD_link_horquilla"/>
    <child link="casterD_link_rueda"/>
    <axis xyz="0 0 1"/>
  </joint>
  <joint name="casterD_joint_rueda_caster" type="fixed">
    <origin rpy="3.1415 0 0" xyz="0.240 -0.188 -0.022"/>
    <parent link="link_base"/>
    <child link="casterD_link_brida"/>
  </joint>
  <link name="casterI_link_brida">
    <inertial>
      <origin rpy="0 0 0" xyz="-5.2042E-18 0 0.0017221"/>
      <mass value="0.2362"/>
      <inertia ixx="0.0002074" ixy="-8.6231E-20" ixz="-4.1413E-22" iyy="0.00030568" iyz="-8.399E-22" izz="0.00051259"/>
    </inertial>
    <visual>
      <origin rpy="0 0 0" xyz="0 0 0"/>
      <geometry>
        <mesh filename="file:///home/duser/install/carrolac_description/share/carrolac_description/meshes/link_brida.STL"/>
      </geometry>
      <material name="">
        <color rgba="0.8 0.0 0.0 1"/>
      </material>
    </visual>
    <collision>
      <origin rpy="0 0 0" xyz="0 0 0"/>
      <geometry>
        <mesh filename="file:///home/duser/install/carrolac_description/share/carrolac_description/meshes/link_brida.STL"/>
      </geometry>
    </collision>
  </link>
  <link name="casterI_link_horquilla">
    <inertial>
      <origin rpy="0 0 0" xyz="1.8908E-07 0.02249 0.050761"/>
      <mass value="0.072224"/>
      <inertia ixx="0.00012363" ixy="8.8179E-10" ixz="4.1929E-10" iyy="0.0001408" iyz="-3.5406E-05" izz="0.000144"/>
    </inertial>
    <visual>
      <origin rpy="0 0 0" xyz="0 0 0"/>
      <geometry>
        <mesh filename="file:///home/duser/install/carrolac_description/share/carrolac_description/meshes/link_horquilla.STL"/>
      </geometry>
      <material name="">
        <color rgba="1.0 1.0 1.0 1"/>
      </material>
    </visual>
    <collision>
      <origin rpy="0 0 0" xyz="0 0 0"/>
      <geometry>
        <mesh filename="file:///home/duser/install/carrolac_description/share/carrolac_description/meshes/link_horquilla.STL"/>
      </geometry>
    </collision>
  </link>
  <joint name="casterI_joint_horquilla" type="continuous">
    <origin rpy="0 0 0" xyz="0 0 0.002"/>
    <parent link="casterI_link_brida"/>
    <child link="casterI_link_horquilla"/>
    <axis xyz="0 0 1"/>
  </joint>
  <link name="casterI_link_rueda">
    <inertial>
      <origin rpy="0 0 0" xyz="0.016549 0.029538 -0.010744"/>
      <mass value="0.97447"/>
      <inertia ixx="0.0036205" ixy="-0.0011336" ixz="-1.1597E-09" iyy="0.0024449" iyz="-7.6933E-10" izz="0.0051466"/>
    </inertial>
    <visual>
      <origin rpy="0 0 0" xyz="0 0 0"/>
      <geometry>
        <mesh filename="file:///home/duser/install/carrolac_description/share/carrolac_description/meshes/link_rueda.STL"/>
      </geometry>
      <material name="">
        <color rgba="0.2 0.2 0.2 1"/>
      </material>
    </visual>
    <collision>
      <origin rpy="0 0 0" xyz="0 0 0"/>
      <geometry>
        <mesh filename="file:///home/duser/install/carrolac_description/share/carrolac_description/meshes/link_rueda.STL"/>
      </geometry>
    </collision>
  </link>
  <gazebo reference="casterI_link_rueda">
    <collision>
      <surface>
        <contact>
          <elastic_modulus>1</elastic_modulus>
          <ode>
            <kp>1</kp>
          </ode>
        </contact>
      </surface>
    </collision>
  </gazebo>
  <joint name="casterI_joint_rueda" type="continuous">
    <origin rpy="-1.5708 0 -1.5708" xyz="0.010744 0.057553 0.105"/>
    <parent link="casterI_link_horquilla"/>
    <child link="casterI_link_rueda"/>
    <axis xyz="0 0 1"/>
  </joint>
  <joint name="casterI_joint_rueda_caster" type="fixed">
    <origin rpy="3.1415 0 0" xyz="0.240 0.188 -0.022"/>
    <parent link="link_base"/>
    <child link="casterI_link_brida"/>
  </joint>
  <link name="modsensorsD_link_base">
    <inertial>
      <origin rpy="0 0 0" xyz="0.060602 -1.1102E-16 -0.0023892"/>
      <mass value="0.15562"/>
      <inertia ixx="0.00087778" ixy="1.0072E-18" ixz="4.7838E-20" iyy="0.00010795" iyz="2.8977E-18" izz="0.00097034"/>
    </inertial>
    <visual>
      <origin rpy="0 0 0" xyz="0 0 0"/>
      <geometry>
        <mesh filename="file:///home/duser/install/carrolac_description/share/carrolac_description/meshes/link_base.STL"/>
      </geometry>
      <material name="">
        <color rgba="1 1 0 1"/>
      </material>
    </visual>
    <collision>
      <origin rpy="0 0 0" xyz="0 0 0"/>
      <geometry>
        <mesh filename="file:///home/duser/install/carrolac_description/share/carrolac_description/meshes/link_base.STL"/>
      </geometry>
    </collision>
  </link>
  <link name="modsensorsD_link_imu">
    <inertial>
      <origin rpy="0 0 0" xyz="0 0 0.002"/>
      <mass value="0.006"/>
      <inertia ixx="1.258E-06" ixy="-2.6936E-23" ixz="4.5723E-27" iyy="4.58E-07" iyz="4.4136E-21" izz="1.7E-06"/>
    </inertial>
    <visual>
      <origin rpy="0 0 0" xyz="0 0 0"/>
      <geometry>
        <mesh filename="file:///home/duser/install/carrolac_description/share/carrolac_description/meshes/link_imu.STL"/>
      </geometry>
      <material name="">
        <color rgba="1 0.16863 0.16863 1"/>
      </material>
    </visual>
    <collision>
      <origin rpy="0 0 0" xyz="0 0 0"/>
      <geometry>
        <mesh filename="file:///home/duser/install/carrolac_description/share/carrolac_description/meshes/link_imu.STL"/>
      </geometry>
    </collision>
  </link>
  <joint name="modsensorsD_joint_imu" type="fixed">
    <origin rpy="0 0 0" xyz="0.03 -0.04 -0.016"/>
    <parent link="modsensorsD_link_base"/>
    <child link="modsensorsD_link_imu"/>
    <axis xyz="0 0 0"/>
  </joint>
  <link name="modsensorsD_link_gopro">
    <inertial>
      <origin rpy="0 0 0" xyz="-0.022189 -0.0095104 -0.0097778"/>
      <mass value="0.049634"/>
      <inertia ixx="2.1379E-05" ixy="3.6313E-09" ixz="-5.7239E-08" iyy="1.0761E-05" iyz="1.9418E-07" izz="1.2183E-05"/>
    </inertial>
    <visual>
      <origin rpy="0 0 0" xyz="0 0 0"/>
      <geometry>
        <mesh filename="file:///home/duser/install/carrolac_description/share/carrolac_description/meshes/link_gopro.STL"/>
      </geometry>
      <material name="">
        <color rgba="0.62745 0.62745 0.62745 1"/>
      </material>
    </visual>
    <collision>
      <origin rpy="0 0 0" xyz="0 0 0"/>
      <geometry>
        <mesh filename="file:///home/duser/install/carrolac_description/share/carrolac_description/meshes/link_gopro.STL"/>
      </geometry>
    </collision>
  </link>
  <joint name="modsensorsD_joint_gopro" type="fixed">
    <origin rpy="0 0 0" xyz="0.145 0.010325 0.0272"/>
    <parent link="modsensorsD_link_base"/>
    <child link="modsensorsD_link_gopro"/>
    <axis xyz="0 0 0"/>
  </joint>
  <link name="modsensorsD_link_lidar">
    <inertial>
      <origin rpy="0 0 0" xyz="0.00010894 1.1005E-05 0.01802"/>
      <mass value="0.04029"/>
      <inertia ixx="7.6882E-06" ixy="-9.9275E-08" ixz="-5.261E-08" iyy="7.6164E-06" iyz="-5.5983E-09" izz="8.2845E-06"/>
    </inertial>
    <visual>
      <origin rpy="0 0 0" xyz="0 0 0"/>
      <geometry>
        <mesh filename="file:///home/duser/install/carrolac_description/share/carrolac_description/meshes/link_lidar.STL"/>
      </geometry>
      <material name="">
        <color rgba="0.79216 0.81961 0.93333 1"/>
      </material>
    </visual>
    <collision>
      <origin rpy="0 0 0" xyz="0 0 0"/>
      <geometry>
        <mesh filename="file:///home/duser/install/carrolac_description/share/carrolac_description/meshes/link_lidar.STL"/>
      </geometry>
    </collision>
  </link>
  <joint name="modsensorsD_joint_lidar" type="fixed">
    <origin rpy="0 0 0" xyz="0.11803 -0.002025 -0.0605"/>
    <parent link="modsensorsD_link_base"/>
    <child link="modsensorsD_link_lidar"/>
    <axis xyz="0 0 0"/>
  </joint>
  <gazebo reference="modsensorsD_link_imu">
    <sensor name="modsensorsD_imu_sensor" type="imu">
      <always_on>1</always_on>
      <update_rate>10.0</update_rate>
      <visualize>true</visualize>
      <topic>imu</topic>
    </sensor>
  </gazebo>
  <gazebo reference="modsensorsD_link_gopro">
    <sensor name="right" type="camera">
      <update_rate>10.0</update_rate>
      <always_on>true</always_on>
      <ignition_frame_id>camera_link_optical</ignition_frame_id>
      <pose>0 -0.12 0 0 0 0</pose>
      <topic>stereo_camera/right/image_raw</topic>
      <horizontal_fov>1.3962634</horizontal_fov>
      <image>
        <width>512</width>
        <height>512</height>
        <format>R8G8B8</format>
      </image>
      <clip>
        <near>0.02</near>
        <far>300</far>
      </clip>
    </sensor>
    <sensor name="left" type="camera">
      <topic>stereo_camera/left/image_raw</topic>
      <update_rate>10.0</update_rate>
      <always_on>true</always_on>
      <ignition_frame_id>camera_link_optical</ignition_frame_id>
      <pose>0 0 0 0 0 0</pose>
      <horizontal_fov>1.3962634</horizontal_fov>
      <image>
        <width>512</width>
        <height>512</height>
        <format>R8G8B8</format>
      </image>
      <clip>
        <near>0.02</near>
        <far>300</far>
      </clip>
    </sensor>
  </gazebo>
  <!--ros2_control name="IgnitionSystem2" type="system">
      <hardware>
        <plugin>ign_ros2_control/IgnitionSystem</plugin>
      </hardware>
      <sensor name="${prefix}_imu_sensor">
        <state_interface name="orientation.x"/>
        <state_interface name="orientation.y"/>
        <state_interface name="orientation.z"/>
        <state_interface name="orientation.w"/>
        <state_interface name="angular_velocity.x"/>
        <state_interface name="angular_velocity.y"/>
        <state_interface name="angular_velocity.z"/>
        <state_interface name="linear_acceleration.x"/>
        <state_interface name="linear_acceleration.y"/>
        <state_interface name="linear_acceleration.z"/>
      </sensor>
    </ros2_control-->
  <joint name="modsensorsD_joint_modulo_sensores" type="fixed">
    <origin rpy="0 0 0" xyz="0.300 0.000 -0.010"/>
    <parent link="link_base"/>
    <child link="modsensorsD_link_base"/>
  </joint>
  <link name="modsbot_link_base">
    <inertial>
      <origin rpy="0 0 0" xyz="-0.17805 -4.4409E-16 -0.0012606"/>
      <mass value="0.29668"/>
      <inertia ixx="0.0014537" ixy="-1.3708E-18" ixz="8.1444E-19" iyy="0.00097455" iyz="-1.9727E-18" izz="0.0023941"/>
    </inertial>
    <visual>
      <origin rpy="0 0 0" xyz="0 0 0"/>
      <geometry>
        <mesh filename="file:///home/duser/install/carrolac_description/share/carrolac_description/meshes/md00_link_base.STL"/>
      </geometry>
      <material name="">
        <color rgba="1 1 0 1"/>
      </material>
    </visual>
    <collision>
      <origin rpy="0 0 0" xyz="0 0 0"/>
      <geometry>
        <mesh filename="file:///home/duser/install/carrolac_description/share/carrolac_description/meshes/md00_link_base.STL"/>
      </geometry>
    </collision>
  </link>
  <link name="modsbot_caster_link_brida">
    <inertial>
      <origin rpy="0 0 0" xyz="-5.2042E-18 0 0.0017221"/>
      <mass value="0.2362"/>
      <inertia ixx="0.0002074" ixy="-8.6231E-20" ixz="-4.1413E-22" iyy="0.00030568" iyz="-8.399E-22" izz="0.00051259"/>
    </inertial>
    <visual>
      <origin rpy="0 0 0" xyz="0 0 0"/>
      <geometry>
        <mesh filename="file:///home/duser/install/carrolac_description/share/carrolac_description/meshes/link_brida.STL"/>
      </geometry>
      <material name="">
        <color rgba="0.8 0.0 0.0 1"/>
      </material>
    </visual>
    <collision>
      <origin rpy="0 0 0" xyz="0 0 0"/>
      <geometry>
        <mesh filename="file:///home/duser/install/carrolac_description/share/carrolac_description/meshes/link_brida.STL"/>
      </geometry>
    </collision>
  </link>
  <link name="modsbot_caster_link_horquilla">
    <inertial>
      <origin rpy="0 0 0" xyz="1.8908E-07 0.02249 0.050761"/>
      <mass value="0.072224"/>
      <inertia ixx="0.00012363" ixy="8.8179E-10" ixz="4.1929E-10" iyy="0.0001408" iyz="-3.5406E-05" izz="0.000144"/>
    </inertial>
    <visual>
      <origin rpy="0 0 0" xyz="0 0 0"/>
      <geometry>
        <mesh filename="file:///home/duser/install/carrolac_description/share/carrolac_description/meshes/link_horquilla.STL"/>
      </geometry>
      <material name="">
        <color rgba="1.0 1.0 1.0 1"/>
      </material>
    </visual>
    <collision>
      <origin rpy="0 0 0" xyz="0 0 0"/>
      <geometry>
        <mesh filename="file:///home/duser/install/carrolac_description/share/carrolac_description/meshes/link_horquilla.STL"/>
      </geometry>
    </collision>
  </link>
  <joint name="modsbot_caster_joint_horquilla" type="continuous">
    <origin rpy="0 0 0" xyz="0 0 0.002"/>
    <parent link="modsbot_caster_link_brida"/>
    <child link="modsbot_caster_link_horquilla"/>
    <axis xyz="0 0 1"/>
  </joint>
  <link name="modsbot_caster_link_rueda">
    <inertial>
      <origin rpy="0 0 0" xyz="0.016549 0.029538 -0.010744"/>
      <mass value="0.97447"/>
      <inertia ixx="0.0036205" ixy="-0.0011336" ixz="-1.1597E-09" iyy="0.0024449" iyz="-7.6933E-10" izz="0.0051466"/>
    </inertial>
    <visual>
      <origin rpy="0 0 0" xyz="0 0 0"/>
      <geometry>
        <mesh filename="file:///home/duser/install/carrolac_description/share/carrolac_description/meshes/link_rueda.STL"/>
      </geometry>
      <material name="">
        <color rgba="0.2 0.2 0.2 1"/>
      </material>
    </visual>
    <collision>
      <origin rpy="0 0 0" xyz="0 0 0"/>
      <geometry>
        <mesh filename="file:///home/duser/install/carrolac_description/share/carrolac_description/meshes/link_rueda.STL"/>
      </geometry>
    </collision>
  </link>
  <gazebo reference="modsbot_caster_link_rueda">
    <collision>
      <surface>
        <contact>
          <elastic_modulus>1</elastic_modulus>
          <ode>
            <kp>1</kp>
          </ode>
        </contact>
      </surface>
    </collision>
  </gazebo>
  <joint name="modsbot_caster_joint_rueda" type="continuous">
    <origin rpy="-1.5708 0 -1.5708" xyz="0.010744 0.057553 0.105"/>
    <parent link="modsbot_caster_link_horquilla"/>
    <child link="modsbot_caster_link_rueda"/>
    <axis xyz="0 0 1"/>
  </joint>
  <joint name="modsbot_joint_rueda_caster" type="fixed">
    <!--	  <origin xyz="-0.215 0.000 -0.011" rpy="3.1415 0 0"/>-->
    <origin rpy="3.1415 0 0" xyz="-0.215 0.000 -0.014"/>
    <parent link="modsbot_link_base"/>
    <child link="modsbot_caster_link_brida"/>
  </joint>
  <joint name="modsbot_joint_moduloscorbot" type="fixed">
    <origin rpy="0 0 0" xyz="-0.300 0.000 -0.010"/>
    <parent link="link_base"/>
    <child link="modsbot_link_base"/>
  </joint>
  <gazebo>
    <self_collide>false</self_collide>
    <plugin filename="ignition-gazebo-joint-state-publisher-system" name="gz::sim::systems::JointStatePublisher"/>
    <plugin filename="ign_ros2_control-system" name="ign_ros2_control::IgnitionROS2ControlPlugin">
      <parameters>/home/duser/install/carrolac_gazebo/share/carrolac_gazebo/config/modsensors_controller_velocity.yaml</parameters>
    </plugin>
    <plugin filename="ignition-gazebo-imu-system" name="ignition::gazebo::systems::Imu">
    </plugin>
    <plugin filename="libignition-gazebo-sensors-system.so" name="ignition::gazebo::systems::Sensors">
	</plugin>
  </gazebo>
</robot>
